Workbook

Sheet Assumptions
A1: AstraCore Neo FMEDA v2 (drop 0.43): v1's base failure rates unchanged (rows 4-19, the derived rates 22-26); row 32 adds the weight buffer's storage, which v1 had no row for. Blue = inputs; yellow = assumptions to replace with foundry data (ISO 26262-11).
A3: Parameter | B3: Value | C3: Unit | D3: Source / note
A4: Die permanent base failure rate (whole 210 mm² die) | B4: 200 | C4: FIT | D4: Assumption, order of magnitude for a large N5-class automotive die; replace with foundry data
A5: Die area | B5: 210 | C5: mm² | D5: Spec v2.0 physical estimate
A6: MAC core area incl. buffers (one core) | B6: 0.47 | C6: mm² | D6: 30 mm² for 64 cores from the die estimate
A7: SRAM soft-error rate | B7: 600 | C7: FIT/Mbit | D7: Assumption; replace with foundry SER at ground level, Grade 2 mission profile
A8: Flip-flop soft-error rate | B8: 100 | C8: FIT/Mbit | D8: Assumption; replace with foundry SER
A9: Accumulator SRAM per core | B9: 0.5 | C9: Mbit | D9: 512 rows × 32 columns × 32 bit = 64 KB
A10: Activation buffer SRAM per core | B10: 0.25 | C10: Mbit | D10: 4096 pixels × 32 channels × 8 bit = 32 KB
A11: Weight registers per core (active + shadow) | B11: 0.0176 | C11: Mbit | D11: 2 × 1056 PEs × 8.3 bit average incl. check column
A12: Pipeline and control flops per core | B12: 0.04 | C12: Mbit | D12: x/psum/token registers, skew and deskew, feeder, accumulator read registers
A13: Mission lifetime | B13: 131400 | C13: h | D13: 15 years × 8,760 h; vehicle operating hours are lower, kept conservative
A14: ASIL-B(D) target SPFM | B14: 0.9 | D14: ISO 26262-5 Table 4
A15: ASIL-B(D) target LFM | B15: 0.6 | D15: ISO 26262-5 Table 5
A16: ASIL-B(D) target PMHF | B16: 100 | C16: FIT | D16: ISO 26262-5 Table 6
A17: ASIL-D target SPFM | B17: 0.99 | D17: ISO 26262-5 Table 4
A18: ASIL-D target LFM | B18: 0.9 | D18: ISO 26262-5 Table 5
A19: ASIL-D target PMHF | B19: 10 | C19: FIT | D19: ISO 26262-5 Table 6
A21: Derived (formulas)
A22: Permanent failure rate of one MAC core | B22: =B4*B6/B5 | C22: FIT
A23: Transient failure rate, accumulator SRAM | B23: =B7*B9 | C23: FIT
A24: Transient failure rate, activation buffer SRAM | B24: =B7*B10 | C24: FIT
A25: Transient failure rate, weight registers | B25: =B8*B11 | C25: FIT
A26: Transient failure rate, pipeline and control flops | B26: =B8*B12 | C26: FIT
A31: v2 addition
A32: Weight buffer SRAM per core (v2 addition) | B32: 0.457 | C32: Mbit | D32: WBUF_DEPTH 1024 entries x 468 bits (the 2:4 sparse-capable 32x32 core: 376 bits in 12 SECDED lanes of 39 bits) = 479,232 bits; v1 has no row for it
A33: Transient failure rate, weight buffer SRAM | B33: =B7*B32 | C33: FIT
A35: Observations, not changed here so that v2 compares with v1 like for like: the silicon activation buffer is ABUF_DEPTH 2048 x 32 bytes = 0.5 Mbit (v1: 0.25 Mbit, and its note's 4096 x 32 x 8 bit is 1 Mbit); the accumulator of the NCHK = 4 core is 512 x 36 x 32 bit = 0.5625 Mbit (v1: 0.5).

Sheet FMEDA_core_v2
A1: FMEDA v2 (drop 0.43), one MAC core: v1's rows with the diagnostic coverage the fault campaign measured (02_dv/dv/cocotb/faults/, the faults job). Per row: the faults that measure it (campaign selection), their outcomes, F_safe = the bit-weighted fraction masked in the workload (no violation, ISO 26262's safe faults), DC_RF = detected / (detected + dangerous), bit-weighted, with its 95 % Wilson interval. λ_SPF/RF = λ x SR x FMD x SPF x (1 - F_safe) x (1 - DC_RF). Rows marked 'claim' keep v1's value and say why. Campaign: run 192 (workflow_dispatch on d2-faults at e3fbc93784c7bce3702383a2da91cd7760a0d180) Tue Oct 13 06:24:13 UTC 2026.
A3: Block | B3: Failure mode | C3: Fault type | D3: λ (FIT) | E3: SR | F3: FMD | G3: SPF | H3: Safety mechanism | I3: Campaign selection | J3: Faults | K3: Detected | L3: Masked | M3: Dangerous (incl. hang) | N3: F_safe (measured) | O3: DC_RF measured | P3: DC_RF 95 % CI (n_eff) | Q3: DC_RF used | R3: λ_SPF/RF (FIT) | S3: MPF | T3: Latent-fault mechanism | U3: DC_L | V3: λ_MPF,L (FIT) | W3: Formal proofs (formal job) | X3: v1 DC_RF | Y3: v1 λ_SPF/RF (FIT) | Z3: Basis / evidence
A4: PE array datapath (1,056 MACs) | B4: Wrong product or sum, single-point | C4: permanent | D4: =Assumptions!$B$22*0.55 | E4: 1 | F4: 0.9 | G4: 1 | H4: ABFT check column: any single-point error in a row flips the row equality | I4: core: neo_mac_core / stuck-at / weight registers excluded | J4: 921 | K4: 509 | L4: 367 | M4: 45 | N4: 0.39847991 | O4: 0.91877256 | P4: 89.3 % .. 93.9 % (554) | Q4: 0.91877256 | R4: =D4*E4*F4*G4*(1-N4)*(1-Q4) | S4: 0 | T4: n/a (detected faults lead to safe state) | U4: 0 | V4: =D4*E4*F4*S4*(1-U4) | W4: abft_checker PASS (prove, 0.4 s) | X4: 0.99 | Y4: 0.0022157143 | Z4: measured
A5: PE array datapath (1,056 MACs) | B5: Dual faults that cancel in the checksum | C5: permanent | D5: =Assumptions!$B$22*0.55 | E5: 1 | F5: 0.1 | G5: 1 | H5: Periodic in-field LBIST of the core | I5: - | N5: 0 | Q5: 0.9 | R5: =D5*E5*F5*G5*(1-N5)*(1-Q5) | S5: 0 | T5: n/a | U5: 0 | V5: =D5*E5*F5*S5*(1-U5) | X5: 0.9 | Y5: 0.0024619048 | Z5: claim; dual faults: a single-fault campaign does not make them; LBIST (IP) is the mechanism
A6: Weight registers (active + shadow) | B6: Bit flip in a stored weight | C6: transient | D6: =Assumptions!$B$25*1 | E6: 1 | F6: 1 | G6: 1 | H6: ABFT (corrupted weight flags every row) and reload per tile | I6: core: neo_mac_core / flips / weight registers only | J6: 181 | K6: 42 | L6: 139 | M6: 0 | N6: 0.7679558 | O6: 1 | P6: 91.6 % .. 100.0 % (42) | Q6: 1 | R6: =D6*E6*F6*G6*(1-N6)*(1-Q6) | S6: 0 | T6: n/a | U6: 0 | V6: =D6*E6*F6*S6*(1-U6) | W6: abft_checker PASS (prove, 0.4 s) | X6: 0.99 | Y6: 0.0176 | Z6: measured
A7: Weight registers (active + shadow) | B7: Stuck bit in a weight register | C7: permanent | D7: =Assumptions!$B$22*0.05 | E7: 1 | F7: 1 | G7: 1 | H7: ABFT | I7: core: neo_mac_core / stuck-at / weight registers only | J7: 137 | K7: 64 | L7: 73 | M7: 0 | N7: 0.53284672 | O7: 1 | P7: 94.3 % .. 100.0 % (64) | Q7: 1 | R7: =D7*E7*F7*G7*(1-N7)*(1-Q7) | S7: 0 | T7: n/a | U7: 0 | V7: =D7*E7*F7*S7*(1-U7) | W7: abft_checker PASS (prove, 0.4 s) | X7: 0.99 | Y7: 0.00022380952 | Z7: measured
A8: x / psum / token chains, skew, deskew | B8: Bit flip in a pipeline register | C8: transient | D8: =Assumptions!$B$26*0.7 | E8: 1 | F8: 1 | G8: 1 | H8: ABFT for data chains; token/valid parity | I8: core: neo_mac_core / flips / weight registers excluded | J8: 1032 | K8: 424 | L8: 574 | M8: 34 | N8: 0.55620155 | O8: 0.92576419 | P8: 89.8 % .. 94.6 % (458) | Q8: 0.92576419 | R8: =D8*E8*F8*G8*(1-N8)*(1-Q8) | S8: 0 | T8: n/a | U8: 0 | V8: =D8*E8*F8*S8*(1-U8) | W8: abft_checker PASS (prove, 0.4 s) | X8: 0.95 | Y8: 0.14 | Z8: measured
A9: x / psum / token chains, skew, deskew | B9: Stuck pipeline register | C9: permanent | D9: =Assumptions!$B$22*0.1 | E9: 1 | F9: 1 | G9: 1 | H9: ABFT; LBIST | I9: core: neo_mac_core / stuck-at / weight registers excluded | J9: 921 | K9: 509 | L9: 367 | M9: 45 | N9: 0.39847991 | O9: 0.91877256 | P9: 89.3 % .. 93.9 % (554) | Q9: 0.91877256 | R9: =D9*E9*F9*G9*(1-N9)*(1-Q9) | S9: 0 | T9: n/a | U9: 0 | V9: =D9*E9*F9*S9*(1-U9) | W9: abft_checker PASS (prove, 0.4 s) | X9: 0.97 | Y9: 0.0013428571 | Z9: measured
A10: ABFT checker (array output) | B10: Stuck at 'no error' (false negative) | C10: permanent | D10: =Assumptions!$B$22*0.02 | E10: 1 | F10: 0.5 | G10: 0 | H10: none needed alone (does not violate SG by itself) | I10: core: neo_mac_core.abft_checker, acc_bank.abft_checker | J10: 70 | K10: 35 | L10: 35 | M10: 0 | N10: 0 | Q10: 0 | R10: =D10*E10*F10*G10*(1-N10)*(1-Q10) | S10: 1 | T10: Periodic self-test: inject one known fault per FTTI via the fault hook, expect a flag | U10: 0.9 | V10: =D10*E10*F10*S10*(1-U10) | W10: abft_checker PASS (prove, 0.4 s) | X10: 0 | Y10: 0 | Z10: claim; latent: the island's periodic self-test is the mechanism (not part of a C1 run); the faults show what a checker fault alone does (no wrong result expected: SPF 0); checker faults: 70 run, 35 detected (safe side), 35 masked, 0 dangerous
A11: ABFT checker (array output) | B11: False positive (spurious error) | C11: permanent | D11: =Assumptions!$B$22*0.02 | E11: 1 | F11: 0.5 | G11: 0 | H11: safe failure: leads to safe state | I11: - | N11: 0 | Q11: 0 | R11: =D11*E11*F11*G11*(1-N11)*(1-Q11) | S11: 0 | T11: n/a | U11: 0 | V11: =D11*E11*F11*S11*(1-U11) | X11: 0 | Y11: 0 | Z11: claim; safe failure mode
A12: Accumulator SRAM (64 KB) | B12: Single-bit upset | C12: transient | D12: =Assumptions!$B$23*0.97 | E12: 1 | F12: 1 | G12: 1 | H12: SECDED ECC (correct) and ABFT at drain (independent detection) | I12: core: acc_bank.sram / flips | J12: 200 | K12: 121 | L12: 79 | M12: 0 | N12: 0.395 | O12: 1 | P12: 96.9 % .. 100.0 % (121) | Q12: 1 | R12: =D12*E12*F12*G12*(1-N12)*(1-Q12) | S12: 0 | T12: n/a | U12: 0 | V12: =D12*E12*F12*S12*(1-U12) | W12: abft_checker PASS (prove, 0.4 s) | X12: 0.9999 | Y12: 0.0291 | Z12: measured
A13: Accumulator SRAM (64 KB) | B13: Multi-bit upset in one word | C13: transient | D13: =Assumptions!$B$23*0.03 | E13: 1 | F13: 1 | G13: 1 | H13: SECDED detect + ABFT at drain | I13: - | N13: 0 | Q13: 0.999 | R13: =D13*E13*F13*G13*(1-N13)*(1-Q13) | S13: 0 | T13: n/a | U13: 0 | V13: =D13*E13*F13*S13*(1-U13) | X13: 0.999 | Y13: 0.009 | Z13: claim; multi-bit upsets are not injected (single-bit campaign); the single-bit row measures the same mechanism (ABFT at drain)
A14: Accumulator SRAM (64 KB) | B14: Stuck cell or decoder fault | C14: permanent | D14: =Assumptions!$B$22*0.08 | E14: 1 | F14: 1 | G14: 1 | H14: ECC, ABFT at drain, MBIST at boot | I14: core: acc_bank.sram / stuck-at | J14: 41 | K14: 18 | L14: 23 | M14: 0 | N14: 0.56097561 | O14: 1 | P14: 82.4 % .. 100.0 % (18) | Q14: 1 | R14: =D14*E14*F14*G14*(1-N14)*(1-Q14) | S14: 0 | T14: n/a | U14: 0 | V14: =D14*E14*F14*S14*(1-U14) | W14: abft_checker PASS (prove, 0.4 s) | X14: 0.999 | Y14: 3.5809524e-05 | Z14: measured
A15: Activation buffer SRAM (32 KB) | B15: Single-bit upset | C15: transient | D15: =Assumptions!$B$24*0.97 | E15: 1 | F15: 1 | G15: 1 | H15: SECDED ECC; end-to-end CRC from the DMA (ABFT cannot see a wrong input) | I15: core: act_feeder.sram / flips | J15: 199 | K15: 0 | L15: 160 | M15: 39 | N15: 0.8040201 | O15: 0 | P15: 0.0 % .. 9.0 % (39) | Q15: 0 | R15: =D15*E15*F15*G15*(1-N15)*(1-Q15) | S15: 0 | T15: n/a | U15: 0 | V15: =D15*E15*F15*S15*(1-U15) | X15: 0.999 | Y15: 0.1455 | Z15: measured
A16: Activation buffer SRAM (32 KB) | B16: Multi-bit upset or stuck cell (transient part) | C16: transient | D16: =Assumptions!$B$24*0.03 | E16: 1 | F16: 1 | G16: 1 | H16: SECDED detect, E2E CRC, MBIST | I16: core: act_feeder.sram / flips | J16: 199 | K16: 0 | L16: 160 | M16: 39 | N16: 0.8040201 | O16: 0 | P16: 0.0 % .. 9.0 % (39) | Q16: 0 | R16: =D16*E16*F16*G16*(1-N16)*(1-Q16) | S16: 0 | T16: n/a | U16: 0 | V16: =D16*E16*F16*S16*(1-U16) | X16: 0.99 | Y16: 0.045 | Z16: measured; multi-bit upsets measured by the single-bit faults: the array carries no code, so what one flipped bit does unseen two do
A17: Activation buffer SRAM (32 KB) | B17: Multi-bit upset or stuck cell (permanent part) | C17: permanent | D17: =Assumptions!$B$22*0.05 | E17: 1 | F17: 1 | G17: 1 | H17: SECDED detect, E2E CRC, MBIST | I17: core: act_feeder.sram / stuck-at | J17: 44 | K17: 0 | L17: 39 | M17: 5 | N17: 0.88636364 | O17: 0 | P17: 0.0 % .. 43.4 % (5) | Q17: 0 | R17: =D17*E17*F17*G17*(1-N17)*(1-Q17) | S17: 0 | T17: n/a | U17: 0 | V17: =D17*E17*F17*S17*(1-U17) | X17: 0.99 | Y17: 0.00022380952 | Z17: measured
A18: Feeder address generator and run FSM | B18: Wrong address, wrong sequence, early stop | C18: permanent | D18: =Assumptions!$B$22*0.06 | E18: 1 | F18: 1 | G18: 1 | H18: Duplicated address generator with comparator (DCLS-style) | I18: core: act_feeder, act_feeder.macro / stuck-at | J18: 37 | K18: 26 | L18: 11 | M18: 0 | N18: 0.40988907 | O18: 1 | P18: 79.5 % .. 100.0 % (15) | Q18: 1 | R18: =D18*E18*F18*G18*(1-N18)*(1-Q18) | S18: 0 | T18: n/a | U18: 0 | V18: =D18*E18*F18*S18*(1-U18) | X18: 0.99 | Y18: 0.00026857143 | Z18: measured
A19: Feeder address generator and run FSM | B19: Bit flip in counters | C19: transient | D19: =Assumptions!$B$26*0.15 | E19: 1 | F19: 1 | G19: 1 | H19: Duplicated address generator with comparator | I19: core: act_feeder, act_feeder.macro / flips | J19: 38 | K19: 15 | L19: 23 | M19: 0 | N19: 0.61483819 | O19: 1 | P19: 73.0 % .. 100.0 % (10) | Q19: 1 | R19: =D19*E19*F19*G19*(1-N19)*(1-Q19) | S19: 0 | T19: n/a | U19: 0 | V19: =D19*E19*F19*S19*(1-U19) | X19: 0.99 | Y19: 0.006 | Z19: measured
A20: Accumulator write/read control and index pipeline | B20: Wrong row index or first flag (permanent part) | C20: permanent | D20: =Assumptions!$B$22*0.03 | E20: 1 | F20: 1 | G20: 1 | H20: Parity on index/first delay lines; ABFT at drain catches mixed rows only partially | I20: core: acc_bank, acc_bank.macro, neo_mac_core_v02 / stuck-at | J20: 62 | K20: 22 | L20: 21 | M20: 19 | N20: 0.44242732 | O20: 0.45954393 | P20: 29.6 % .. 63.3 % (30) | Q20: 0.45954393 | R20: =D20*E20*F20*G20*(1-N20)*(1-Q20) | S20: 0 | T20: n/a | U20: 0 | V20: =D20*E20*F20*S20*(1-U20) | X20: 0.95 | Y20: 0.00067142857 | Z20: measured
A21: Accumulator write/read control and index pipeline | B21: Wrong row index or first flag (transient part) | C21: transient | D21: =Assumptions!$B$26*0.15 | E21: 1 | F21: 1 | G21: 1 | H21: Parity on index/first delay lines; ABFT at drain catches mixed rows only partially | I21: core: acc_bank, acc_bank.macro, neo_mac_core_v02 / flips | J21: 63 | K21: 16 | L21: 35 | M21: 12 | N21: 0.61716174 | O21: 0.52272433 | P21: 32.2 % .. 71.7 % (21) | Q21: 0.52272433 | R21: =D21*E21*F21*G21*(1-N21)*(1-Q21) | S21: 0 | T21: n/a | U21: 0 | V21: =D21*E21*F21*S21*(1-U21) | X21: 0.95 | Y21: 0.03 | Z21: measured
A22: Clock and reset distribution in the core | B22: Clock stuck, glitch, reset glitch | C22: permanent | D22: =Assumptions!$B$22*0.02 | E22: 1 | F22: 1 | G22: 1 | H22: Clock monitor and watchdog in the safety island | I22: - | N22: 0 | Q22: 0.9 | R22: =D22*E22*F22*G22*(1-N22)*(1-Q22) | S22: 0 | T22: n/a | U22: 0 | V22: =D22*E22*F22*S22*(1-U22) | X22: 0.9 | Y22: 0.0008952381 | Z22: claim; clock and reset are not flops: not injectable at RTL (the watchdog's hang detection is measured on the tile build)
A23: NoC interface (requests, responses) | B23: Corrupted packet, lost packet (permanent part) | C23: permanent | D23: =Assumptions!$B$22*0.04 | E23: 1 | F23: 1 | G23: 1 | H23: Packet parity/CRC, timeout, sequence numbers | I23: tile: tile_nic, tile_nic.sram, tile_nic.macro, link_packer, link_unpacker / stuck-at | J23: 296 | K23: 21 | L23: 264 | M23: 11 | N23: 0.87324255 | O23: 0.16739085 | P23: 2.6 % .. 60.0 % (5) | Q23: 0.16739085 | R23: =D23*E23*F23*G23*(1-N23)*(1-Q23) | S23: 0 | T23: n/a | U23: 0 | V23: =D23*E23*F23*S23*(1-U23) | W23: crc16_beat_bw4 PASS (prove, 1.3 s); crc16_beat_bw16 PASS (prove, 22.5 s); link_pack_stream PASS (prove, 212.4 s); link_pack_parity PASS (prove, 13.1 s) | X23: 0.99 | Y23: 0.00017904762 | Z23: measured
A24: NoC interface (requests, responses) | B24: Corrupted packet, lost packet (transient part) | C24: transient | D24: =Assumptions!$B$26*0.1 | E24: 1 | F24: 1 | G24: 1 | H24: Packet parity/CRC, timeout, sequence numbers | I24: tile: tile_nic, tile_nic.sram, tile_nic.macro, link_packer, link_unpacker / flips | J24: 360 | K24: 7 | L24: 350 | M24: 3 | N24: 0.99681326 | O24: 0.77410223 | P24: 45.1 % .. 93.5 % (9) | Q24: 0.77410223 | R24: =D24*E24*F24*G24*(1-N24)*(1-Q24) | S24: 0 | T24: n/a | U24: 0 | V24: =D24*E24*F24*S24*(1-U24) | W24: crc16_beat_bw4 PASS (prove, 1.3 s); crc16_beat_bw16 PASS (prove, 22.5 s); link_pack_stream PASS (prove, 212.4 s); link_pack_parity PASS (prove, 13.1 s) | X24: 0.99 | Y24: 0.004 | Z24: measured
A25: Sequencer FSM, run counters, weight-buffer addressing | B25: Wrong run order, wrong tile, early drain (permanent part) | C25: permanent | D25: =Assumptions!$B$22*0.03 | E25: 1 | F25: 1 | G25: 1 | H25: Duplicated sequencer with comparator (lockstep), weight-buffer ECC | I25: core: core_seq, neo_core, wbuf_mem, wbuf_mem.macro / stuck-at | J25: 62 | K25: 45 | L25: 17 | M25: 0 | N25: 0.3847834 | O25: 1 | P25: 82.2 % .. 100.0 % (18) | Q25: 1 | R25: =D25*E25*F25*G25*(1-N25)*(1-Q25) | S25: 0 | T25: n/a | U25: 0 | V25: =D25*E25*F25*S25*(1-U25) | W25: lockstep_core_seq PASS (prove, 1.2 s); ecc39 PASS (prove, 0.4 s) | X25: 0.99 | Y25: 0.00013428571 | Z25: measured
A26: Sequencer FSM, run counters, weight-buffer addressing | B26: Wrong run order, wrong tile, early drain (transient part) | C26: transient | D26: =Assumptions!$B$26*0.05 | E26: 1 | F26: 1 | G26: 1 | H26: Duplicated sequencer with comparator (lockstep), weight-buffer ECC | I26: core: core_seq, neo_core, wbuf_mem, wbuf_mem.macro / flips | J26: 59 | K26: 29 | L26: 30 | M26: 0 | N26: 0.56534171 | O26: 1 | P26: 74.6 % .. 100.0 % (11) | Q26: 1 | R26: =D26*E26*F26*G26*(1-N26)*(1-Q26) | S26: 0 | T26: n/a | U26: 0 | V26: =D26*E26*F26*S26*(1-U26) | W26: lockstep_core_seq PASS (prove, 1.2 s); ecc39 PASS (prove, 0.4 s) | X26: 0.99 | Y26: 0.002 | Z26: measured
A27: Requantization tables and datapath | B27: Wrong scale, zero point or saturation (permanent part) | C27: permanent | D27: =Assumptions!$B$22*0.02 | E27: 1 | F27: 1 | G27: 1 | H27: Table parity and a duplicated requant stage with comparator | I27: core: requant / stuck-at | J27: 130 | K27: 55 | L27: 75 | M27: 0 | N27: 0.57692308 | O27: 1 | P27: 93.5 % .. 100.0 % (55) | Q27: 1 | R27: =D27*E27*F27*G27*(1-N27)*(1-Q27) | S27: 0 | T27: n/a | U27: 0 | V27: =D27*E27*F27*S27*(1-U27) | W27: lockstep_requant PASS (prove, 15.5 s); requant_parity PASS (prove, 1.5 s) | X27: 0.99 | Y27: 8.952381e-05 | Z27: measured
A28: Requantization tables and datapath | B28: Wrong scale, zero point or saturation (transient part) | C28: transient | D28: =Assumptions!$B$26*0.03 | E28: 1 | F28: 1 | G28: 1 | H28: Table parity and a duplicated requant stage with comparator | I28: core: requant / flips | J28: 113 | K28: 10 | L28: 103 | M28: 0 | N28: 0.91150442 | O28: 1 | P28: 72.2 % .. 100.0 % (10) | Q28: 1 | R28: =D28*E28*F28*G28*(1-N28)*(1-Q28) | S28: 0 | T28: n/a | U28: 0 | V28: =D28*E28*F28*S28*(1-U28) | W28: lockstep_requant PASS (prove, 15.5 s); requant_parity PASS (prove, 1.5 s) | X28: 0.99 | Y28: 0.0012 | Z28: measured
A29: Reduce port and partial-sum transfer (K-split) | B29: Corrupted or lost partial-sum row | C29: both | D29: =Assumptions!$B$22*0.01+Assumptions!$B$26*0.02 | E29: 1 | F29: 1 | G29: 1 | H29: Check column travels with the partial sums; drain-time ABFT at the owner; row count in the sequencer | I29: - | N29: 0 | Q29: 0.99 | R29: =D29*E29*F29*G29*(1-N29)*(1-Q29) | S29: 0 | T29: n/a | U29: 0 | V29: =D29*E29*F29*S29*(1-U29) | X29: 0.99 | Y29: 0.0008447619 | Z29: claim; the reduce port is idle in C1 and M1 (no K-split): an M2-class workload is the follow-up
A30: Weight buffer SRAM (v2 addition) | B30: Single-bit upset | C30: transient | D30: =Assumptions!$B$33*0.97 | E30: 1 | F30: 1 | G30: 1 | H30: SECDED (39,32) per lane, corrected on the sequencer's read (wbuf_ce; wbuf_ue for two flips) | I30: core: wbuf_mem.sram / flips | J30: 198 | K30: 77 | L30: 121 | M30: 0 | N30: 0.61111111 | O30: 1 | P30: 95.2 % .. 100.0 % (77) | Q30: 1 | R30: =D30*E30*F30*G30*(1-N30)*(1-Q30) | S30: 0 | T30: n/a | U30: 0 | V30: =D30*E30*F30*S30*(1-U30) | W30: ecc39 PASS (prove, 0.4 s) | Z30: measured
A31: Weight buffer SRAM (v2 addition) | B31: Multi-bit upset in one lane | C31: transient | D31: =Assumptions!$B$33*0.03 | E31: 1 | F31: 1 | G31: 1 | H31: SECDED detects two flips (wbuf_ue); ABFT for a wrong weight | I31: - | N31: 0 | Q31: 0.999 | R31: =D31*E31*F31*G31*(1-N31)*(1-Q31) | S31: 0 | T31: n/a | U31: 0 | V31: =D31*E31*F31*S31*(1-U31) | W31: ecc39 PASS (prove, 0.4 s) | Z31: claim; multi-bit upsets are not injected; v1's value for SECDED-detected multi-bit upsets (the accumulator's row) kept
A33: Totals | D33: =SUM(D4:D31) | R33: =SUM(R4:R31) | V33: =SUM(V4:V31)
A34: Safety-related λ_SR (Σ λ × SR × FMD) | D34: =SUMPRODUCT(D4:D31,E4:E31,F4:F31)

Sheet Metrics_v2
A1: Hardware architectural metrics, one MAC core, v2 (formulas over FMEDA_core_v2) and the comparison with v1
A3: Metric | B3: Value | C3: ASIL-B(D) target | D3: ASIL-D target | E3: Meets ASIL-B(D)? | F3: Meets ASIL-D?
A4: Σ λ_SR (FIT) | B4: =FMEDA_core_v2!$D$34
A5: Σ λ_SPF/RF (FIT) | B5: =FMEDA_core_v2!$R$33
A6: Σ λ_MPF,L (FIT) | B6: =FMEDA_core_v2!$V$33
A7: SPFM | B7: =IF(B4>0,1-B5/B4,0) | C7: =Assumptions!B14 | D7: =Assumptions!B17 | E7: =IF(B7>=C7,"PASS","FAIL") | F7: =IF(B7>=D7,"PASS","FAIL")
A8: LFM | B8: =IF(B4-B5>0,1-B6/(B4-B5),0) | C8: =Assumptions!B15 | D8: =Assumptions!B18 | E8: =IF(B8>=C8,"PASS","FAIL") | F8: =IF(B8>=D8,"PASS","FAIL")
A9: PMHF, first order (FIT) | B9: =B5+B6*B4*Assumptions!B13*0.000000001 | C9: =Assumptions!B16 | D9: =Assumptions!B19 | E9: =IF(B9<=C9,"PASS","FAIL") | F9: =IF(B9<=D9,"PASS","FAIL")
A12: Comparison (values computed by build_fmeda.py; the formulas above give the 'v2 measured' column)
A13: Metric | B13: v1 (claims) | C13: v2 measured | D13: v2, no credit for masked faults | E13: v2, 95 % upper bounds
A14: Core SPFM | B14: 0.99903949 | C14: 0.95946297 | D14: 0.79394818 | E14: 0.93911953
A15: Core LFM | B15: 0.99999902 | C15: 0.99999936 | D15: 0.99999923 | E15: 0.99999935
A16: Core PMHF (FIT) | B16: 0.43901364 | C16: 29.642116 | D16: 150.67224 | E16: 44.517945
A17: Core Σ λ_SPF/RF (FIT) | B17: 0.43898676 | C17: 29.642073 | D17: 150.67219 | E17: 44.517902
A18: Chip SPFM | B18: 0.99990576 | C18: 0.99708256 | D18: 0.98537 | E18: 0.99562691
A19: Chip LFM | B19: 0.99999923 | C19: 0.99999925 | D19: 0.99999924 | E19: 0.99999925
A20: Chip PMHF (FIT) | B20: 62.289951 | C20: 1931.0408 | D20: 9677.0499 | E20: 2893.7268

Sheet Chip_rollup_v2
A1: Chip-level roll-up v2: the MAC core from FMEDA_core_v2, the shared SRAM's permanent faults and the NoC / DMA engines measured on the tile build (stuck-at faults: their λ is permanent), the shared SRAM's soft errors with v1's coverage (its residual is v1's multi-bit assumption; the single-bit faults are the evidence), the other elements as v1. λ_RF = λ_SR x (1 - F_safe) x (1 - DC_RF).
A3: Element | B3: Count | C3: λ_SR per instance (FIT) | D3: F_safe | E3: DC_RF | F3: λ_SM per instance (FIT) | G3: DC_L | H3: λ_SR total | I3: λ_SPF/RF total | J3: λ_MPF,L total | K3: PMHF contribution (FIT) | L3: Mechanism / basis
A4: MAC core (from FMEDA_core_v2) | B4: 64 | C4: =Metrics_v2!B4 | D4: 0 | E4: =1-Metrics_v2!B5/Metrics_v2!B4 | F4: =Metrics_v2!B6 | G4: 0 | H4: =B4*C4 | I4: =B4*C4*(1-D4)*(1-E4) | J4: =B4*F4*(1-G4) | K4: =I4+J4*C4*Assumptions!$B$13*0.000000001 | L4: core sheet: residual and latent from the core sheet
A5: Shared SRAM 128 MB, soft errors | B5: 1 | C5: 614400 | D5: 0 | E5: 0.99995 | F5: 2 | G5: 0.99 | H5: =B5*C5 | I5: =B5*C5*(1-D5)*(1-E5) | J5: =B5*F5*(1-G5) | K5: =I5+J5*C5*Assumptions!$B$13*0.000000001 | L5: v1 (campaign: evidence): SECDED (39,32) per word: proven on the tile mesh (M5, drop 0.9); + 4-way interleaving + scrubbing + ABFT credit at the consumer; λ_SM = ECC/scrubber logic; DC_L = periodic ECC error injection | campaign (tile: sram_bank.sram / flips): 105 faults, 3 detected, 102 masked, 0 dangerous; DC 100.0 % (43.8 % .. 100.0 %) | ecc39 PASS (prove, 0.4 s)
A6: Shared SRAM 128 MB, permanent | B6: 1 | C6: 61.904762 | D6: 0.94625975 | E6: 0.99860921 | F6: 2 | G6: 0.99 | H6: =B6*C6 | I6: =B6*C6*(1-D6)*(1-E6) | J6: =B6*F6*(1-G6) | K6: =I6+J6*C6*Assumptions!$B$13*0.000000001 | L6: measured: ECC, MBIST at boot, repair | campaign (tile: sram_bank.sram, sram_bank.macro, sram_bank, mbist / stuck-at): 111 faults, 14 detected, 95 masked, 2 dangerous; DC 99.9 % (21.8 % .. 100.0 %)
A7: NoC and DMA engines | B7: 1 | C7: 19.047619 | D7: 0.63266811 | E7: 1 | F7: 1 | G7: 0.9 | H7: =B7*C7 | I7: =B7*C7*(1-D7)*(1-E7) | J7: =B7*F7*(1-G7) | K7: =I7+J7*C7*Assumptions!$B$13*0.000000001 | L7: measured: Packet parity/CRC, timeouts, descriptor CRC; λ_SM = checkers | campaign (tile: noc_router, tile_dma, prog_mem, host_if, neo_tile, esm / stuck-at): 187 faults, 73 detected, 114 masked, 0 dangerous; DC 100.0 % (93.8 % .. 100.0 %) | noc_router PASS (prove, 46.9 s)
A8: Safety island (lockstep R52+) | B8: 1 | C8: 4.7619048 | D8: 0 | E8: 0.999 | F8: 0.5 | G8: 0.95 | H8: =B8*C8 | I8: =B8*C8*(1-D8)*(1-E8) | J8: =B8*F8*(1-G8) | K8: =I8+J8*C8*Assumptions!$B$13*0.000000001 | L8: v1: Dual-core lockstep, ECC, watchdogs, self-test
A9: LPDDR5X controller and PHY | B9: 1 | C9: 22.857143 | D9: 0 | E9: 0.99 | F9: 1 | G9: 0.9 | H9: =B9*C9 | I9: =B9*C9*(1-D9)*(1-E9) | J9: =B9*F9*(1-G9) | K9: =I9+J9*C9*Assumptions!$B$13*0.000000001 | L9: v1: Inline ECC, link ECC, loopback test
A10: PCIe, Ethernet, MIPI, ISP | B10: 1 | C10: 25.714286 | D10: 0 | E10: 0.98 | F10: 1.5 | G10: 0.9 | H10: =B10*C10 | I10: =B10*C10*(1-D10)*(1-E10) | J10: =B10*F10*(1-G10) | K10: =I10+J10*C10*Assumptions!$B$13*0.000000001 | L10: v1: CRC, end-to-end protection, frame counters
A11: Clocks, resets, power management | B11: 1 | C11: 8.5714286 | D11: 0 | E11: 0.9 | F11: 0.5 | G11: 0.9 | H11: =B11*C11 | I11: =B11*C11*(1-D11)*(1-E11) | J11: =B11*F11*(1-G11) | K11: =I11+J11*C11*Assumptions!$B$13*0.000000001 | L11: v1: Clock/voltage/temperature monitors
A13: Totals | H13: =SUM(H4:H11) | I13: =SUM(I4:I11) | J13: =SUM(J4:J11) | K13: =SUM(K4:K11)
A15: Chip SPFM | B15: =IF(H13>0,1-I13/H13,0)
A16: Chip LFM | B16: =IF(H13-I13>0,1-J13/(H13-I13),0)
A17: Chip PMHF, first order (FIT) | B17: =K13
A18: Meets ASIL-B(D)? | B18: =IF(AND(B15>=Assumptions!B14,B16>=Assumptions!B15,B17<=Assumptions!B16),"PASS","FAIL")

Sheet Campaign
A1: The fault campaign per block (unweighted within a block: every fault of a block has the same weight)
A3: Build | B3: Block | C3: Faults | D3: Detected | E3: Masked | F3: Dangerous | G3: Hang detected | H3: Hang | I3: DC | J3: DC 95 % CI | K3: Latency median (cycles) | L3: Latency max (cycles)
A4: core | B4: acc_bank | C4: 60 | D4: 20 | E4: 40 | F4: 0 | G4: 0 | H4: 0 | I4: 1 | J4: 83.9 % .. 100.0 % | K4: 1006 | L4: 1462
A5: core | B5: acc_bank.abft_checker | C5: 36 | D5: 13 | E5: 23 | F5: 0 | G5: 0 | H5: 0 | I5: 1 | J5: 77.2 % .. 100.0 % | K5: 752 | L5: 1641
A6: core | B6: acc_bank.macro | C6: 23 | D6: 18 | E6: 5 | F6: 0 | G6: 0 | H6: 0 | I6: 1 | J6: 82.4 % .. 100.0 % | K6: 3 | L6: 52
A7: core | B7: acc_bank.sram | C7: 241 | D7: 139 | E7: 102 | F7: 0 | G7: 0 | H7: 0 | I7: 1 | J7: 97.3 % .. 100.0 % | K7: 795 | L7: 1613
A8: core | B8: act_feeder | C8: 50 | D8: 22 | E8: 26 | F8: 0 | G8: 2 | H8: 0 | I8: 1 | J8: 86.2 % .. 100.0 % | K8: 7 | L8: 578
A9: core | B9: act_feeder.macro | C9: 25 | D9: 17 | E9: 8 | F9: 0 | G9: 0 | H9: 0 | I9: 1 | J9: 81.6 % .. 100.0 % | K9: 3 | L9: 35
A10: core | B10: act_feeder.sram | C10: 243 | D10: 0 | E10: 199 | F10: 44 | G10: 0 | H10: 0 | I10: 0 | J10: 0.0 % .. 8.0 %
A11: core | B11: core_seq | C11: 48 | D11: 19 | E11: 23 | F11: 0 | G11: 6 | H11: 0 | I11: 1 | J11: 86.7 % .. 100.0 % | K11: 2 | L11: 745
A12: core | B12: neo_core | C12: 25 | D12: 15 | E12: 10 | F12: 0 | G12: 0 | H12: 0 | I12: 1 | J12: 79.6 % .. 100.0 % | K12: 7 | L12: 139
A13: core | B13: neo_mac_core | C13: 2271 | D13: 1039 | E13: 1153 | F13: 79 | G13: 0 | H13: 0 | I13: 0.9293381 | J13: 91.3 % .. 94.3 % | K13: 27 | L13: 336
A14: core | B14: neo_mac_core.abft_checker | C14: 34 | D14: 22 | E14: 12 | F14: 0 | G14: 0 | H14: 0 | I14: 1 | J14: 85.1 % .. 100.0 % | K14: 3 | L14: 36
A15: core | B15: neo_mac_core_v02 | C15: 42 | D15: 0 | E15: 11 | F15: 31 | G15: 0 | H15: 0 | I15: 0 | J15: 0.0 % .. 11.0 %
A16: core | B16: requant | C16: 243 | D16: 65 | E16: 178 | F16: 0 | G16: 0 | H16: 0 | I16: 1 | J16: 94.4 % .. 100.0 % | K16: 648 | L16: 1616
A17: core | B17: wbuf_mem | C17: 23 | D17: 16 | E17: 7 | F17: 0 | G17: 0 | H17: 0 | I17: 1 | J17: 80.6 % .. 100.0 % | K17: 1 | L17: 42
A18: core | B18: wbuf_mem.macro | C18: 25 | D18: 18 | E18: 7 | F18: 0 | G18: 0 | H18: 0 | I18: 1 | J18: 82.4 % .. 100.0 % | K18: 9 | L18: 518
A19: core | B19: wbuf_mem.sram | C19: 248 | D19: 90 | E19: 158 | F19: 0 | G19: 0 | H19: 0 | I19: 1 | J19: 95.9 % .. 100.0 % | K19: 411 | L19: 1369
A20: tile | B20: acc_bank | C20: 39 | D20: 15 | E20: 24 | F20: 0 | G20: 0 | H20: 0 | I20: 1 | J20: 79.6 % .. 100.0 % | K20: 1460 | L20: 3439
A21: tile | B21: acc_bank.abft_checker | C21: 27 | D21: 11 | E21: 16 | F21: 0 | G21: 0 | H21: 0 | I21: 1 | J21: 74.1 % .. 100.0 % | K21: 749 | L21: 3293
A22: tile | B22: acc_bank.macro | C22: 24 | D22: 15 | E22: 9 | F22: 0 | G22: 0 | H22: 0 | I22: 1 | J22: 79.6 % .. 100.0 % | K22: 17 | L22: 1322
A23: tile | B23: acc_bank.sram | C23: 119 | D23: 31 | E23: 88 | F23: 0 | G23: 0 | H23: 0 | I23: 1 | J23: 89.0 % .. 100.0 % | K23: 1033 | L23: 3090
A24: tile | B24: act_feeder | C24: 35 | D24: 12 | E24: 20 | F24: 0 | G24: 3 | H24: 0 | I24: 1 | J24: 79.6 % .. 100.0 % | K24: 12 | L24: 1203
A25: tile | B25: act_feeder.macro | C25: 19 | D25: 9 | E25: 10 | F25: 0 | G25: 0 | H25: 0 | I25: 1 | J25: 70.1 % .. 100.0 % | K25: 31 | L25: 1459
A26: tile | B26: act_feeder.sram | C26: 109 | D26: 0 | E26: 90 | F26: 19 | G26: 0 | H26: 0 | I26: 0 | J26: 0.0 % .. 16.8 %
A27: tile | B27: core_seq | C27: 37 | D27: 15 | E27: 17 | F27: 0 | G27: 5 | H27: 0 | I27: 1 | J27: 83.9 % .. 100.0 % | K27: 3 | L27: 2690
A28: tile | B28: esm | C28: 31 | D28: 13 | E28: 18 | F28: 0 | G28: 0 | H28: 0 | I28: 1 | J28: 77.2 % .. 100.0 % | K28: 1 | L28: 2
A29: tile | B29: host_if | C29: 162 | D29: 99 | E29: 61 | F29: 1 | G29: 1 | H29: 0 | I29: 0.99009901 | J29: 94.6 % .. 99.8 % | K29: 3 | L29: 211
A30: tile | B30: link_packer | C30: 18 | D30: 0 | E30: 15 | F30: 1 | G30: 2 | H30: 0 | I30: 0.66666667 | J30: 20.8 % .. 93.9 % | K30: 7582 | L30: 7582
A31: tile | B31: link_unpacker | C31: 18 | D31: 0 | E31: 18 | F31: 0 | G31: 0 | H31: 0
A32: tile | B32: mbist | C32: 23 | D32: 1 | E32: 20 | F32: 2 | G32: 0 | H32: 0 | I32: 0.33333333 | J32: 6.1 % .. 79.2 % | K32: 2 | L32: 2
A33: tile | B33: neo_core | C33: 20 | D33: 10 | E33: 10 | F33: 0 | G33: 0 | H33: 0 | I33: 1 | J33: 72.2 % .. 100.0 % | K33: 3 | L33: 804
A34: tile | B34: neo_mac_core | C34: 729 | D34: 376 | E34: 352 | F34: 1 | G34: 0 | H34: 0 | I34: 0.99734748 | J34: 98.5 % .. 100.0 % | K34: 45 | L34: 2002
A35: tile | B35: neo_mac_core.abft_checker | C35: 27 | D35: 18 | E35: 9 | F35: 0 | G35: 0 | H35: 0 | I35: 1 | J35: 82.4 % .. 100.0 % | K35: 4 | L35: 938
A36: tile | B36: neo_mac_core_v02 | C36: 27 | D36: 0 | E36: 17 | F36: 10 | G36: 0 | H36: 0 | I36: 0 | J36: 0.0 % .. 27.8 %
A37: tile | B37: neo_tile | C37: 20 | D37: 14 | E37: 6 | F37: 0 | G37: 0 | H37: 0 | I37: 1 | J37: 78.5 % .. 100.0 % | K37: 2 | L37: 2
A38: tile | B38: noc_router | C38: 95 | D38: 8 | E38: 84 | F38: 0 | G38: 3 | H38: 0 | I38: 1 | J38: 74.1 % .. 100.0 % | K38: 25 | L38: 2890
A39: tile | B39: prog_mem | C39: 20 | D39: 15 | E39: 5 | F39: 0 | G39: 0 | H39: 0 | I39: 1 | J39: 79.6 % .. 100.0 % | K39: 2 | L39: 2
A40: tile | B40: requant | C40: 158 | D40: 40 | E40: 118 | F40: 0 | G40: 0 | H40: 0 | I40: 1 | J40: 91.2 % .. 100.0 % | K40: 1780 | L40: 3491
A41: tile | B41: sram_bank | C41: 23 | D41: 12 | E41: 11 | F41: 0 | G41: 0 | H41: 0 | I41: 1 | J41: 75.7 % .. 100.0 % | K41: 2 | L41: 2
...

Sheet Undetected
A1: Dangerous faults (wrong results, no cause) and hangs without a cause
A3: Build | B3: Node | C3: Block | D3: Flop | E3: Bit | F3: Type | G3: Cycle | H3: Outcome | I3: Result words wrong
A4: core | C4: act_feeder.sram | D4: u_dp.u_feeder.u_mem.mem[0] | E4: 11 | F4: flip | G4: 187 | H4: dangerous | I4: 17
A5: core | C5: act_feeder.sram | D5: u_dp.u_feeder.u_mem.mem[10] | E5: 168 | F5: flip | G5: 64 | H5: dangerous | I5: 58
A6: core | C6: act_feeder.sram | D6: u_dp.u_feeder.u_mem.mem[17] | E6: 146 | F6: flip | G6: 496 | H6: dangerous | I6: 9
A7: core | C7: act_feeder.sram | D7: u_dp.u_feeder.u_mem.mem[19] | E7: 205 | F7: flip | G7: 467 | H7: dangerous | I7: 69
A8: core | C8: act_feeder.sram | D8: u_dp.u_feeder.u_mem.mem[19] | E8: 96 | F8: flip | G8: 676 | H8: dangerous | I8: 27
A9: core | C9: act_feeder.sram | D9: u_dp.u_feeder.u_mem.mem[20] | E9: 200 | F9: flip | G9: 528 | H9: dangerous | I9: 29
A10: core | C10: act_feeder.sram | D10: u_dp.u_feeder.u_mem.mem[23] | E10: 124 | F10: sa1 | G10: 654 | H10: dangerous | I10: 72
A11: core | C11: act_feeder.sram | D11: u_dp.u_feeder.u_mem.mem[24] | E11: 251 | F11: flip | G11: 268 | H11: dangerous | I11: 83
A12: core | C12: act_feeder.sram | D12: u_dp.u_feeder.u_mem.mem[25] | E12: 219 | F12: flip | G12: 295 | H12: dangerous | I12: 79
A13: core | C13: act_feeder.sram | D13: u_dp.u_feeder.u_mem.mem[26] | E13: 70 | F13: flip | G13: 670 | H13: dangerous | I13: 89
A14: core | C14: act_feeder.sram | D14: u_dp.u_feeder.u_mem.mem[28] | E14: 52 | F14: flip | G14: 865 | H14: dangerous | I14: 43
A15: core | C15: act_feeder.sram | D15: u_dp.u_feeder.u_mem.mem[29] | E15: 197 | F15: flip | G15: 88 | H15: dangerous | I15: 72
... A157: core | C157: neo_mac_core_v02 | D157: u_dp.u_idx_dl.pipe[9] | E157: 0 | F157: flip | G157: 1369 | H157: dangerous | I157: 28
A158: tile | B158: 0 | C158: act_feeder.sram | D158: u_mesh.g_y[0].g_x[0].u_t.u_core.u_dp.u_feeder.u_mem.mem[0] | E158: 48 | F158: flip | G158: 54 | H158: dangerous | I158: 32
A159: tile | B159: 0 | C159: act_feeder.sram | D159: u_mesh.g_y[0].g_x[0].u_t.u_core.u_dp.u_feeder.u_mem.mem[11] | E159: 118 | F159: sa1 | G159: 1557 | H159: dangerous | I159: 72
A160: tile | B160: 0 | C160: act_feeder.sram | D160: u_mesh.g_y[0].g_x[0].u_t.u_core.u_dp.u_feeder.u_mem.mem[12] | E160: 250 | F160: flip | G160: 2075 | H160: dangerous | I160: 48
A161: tile | B161: 0 | C161: act_feeder.sram | D161: u_mesh.g_y[0].g_x[0].u_t.u_core.u_dp.u_feeder.u_mem.mem[13] | E161: 249 | F161: flip | G161: 1909 | H161: dangerous | I161: 72
A162: tile | B162: 0 | C162: act_feeder.sram | D162: u_mesh.g_y[0].g_x[0].u_t.u_core.u_dp.u_feeder.u_mem.mem[14] | E162: 175 | F162: flip | G162: 655 | H162: dangerous | I162: 48
A163: tile | B163: 0 | C163: act_feeder.sram | D163: u_mesh.g_y[0].g_x[0].u_t.u_core.u_dp.u_feeder.u_mem.mem[19] | E163: 9 | F163: sa0 | G163: 1164 | H163: dangerous | I163: 48
A164: tile | B164: 0 | C164: act_feeder.sram | D164: u_mesh.g_y[0].g_x[0].u_t.u_core.u_dp.u_feeder.u_mem.mem[1] | E164: 4 | F164: flip | G164: 1022 | H164: dangerous | I164: 47
A165: tile | B165: 0 | C165: act_feeder.sram | D165: u_mesh.g_y[0].g_x[0].u_t.u_core.u_dp.u_feeder.u_mem.mem[20] | E165: 152 | F165: flip | G165: 706 | H165: dangerous | I165: 32
A166: tile | B166: 0 | C166: act_feeder.sram | D166: u_mesh.g_y[0].g_x[0].u_t.u_core.u_dp.u_feeder.u_mem.mem[20] | E166: 218 | F166: flip | G166: 1054 | H166: dangerous | I166: 31
A167: tile | B167: 0 | C167: act_feeder.sram | D167: u_mesh.g_y[0].g_x[0].u_t.u_core.u_dp.u_feeder.u_mem.mem[20] | E167: 210 | F167: flip | G167: 1219 | H167: dangerous | I167: 31
A168: tile | B168: 0 | C168: act_feeder.sram | D168: u_mesh.g_y[0].g_x[0].u_t.u_core.u_dp.u_feeder.u_mem.mem[26] | E168: 77 | F168: flip | G168: 1995 | H168: dangerous | I168: 72
A169: tile | B169: 0 | C169: act_feeder.sram | D169: u_mesh.g_y[0].g_x[0].u_t.u_core.u_dp.u_feeder.u_mem.mem[27] | E169: 165 | F169: flip | G169: 2630 | H169: dangerous | I169: 48
... A204: tile | B204: 0 | C204: tile_nic.sram | D204: u_mesh.g_y[0].g_x[0].u_t.u_nic.u_dfifo.mem[21] | E204: 24 | F204: sa0 | G204: 1034 | H204: dangerous | I204: 1

Sheet Formal
A1: The formal job's proofs (Formal report -- SymbiYosys (2026-10-13 06:38:17 UTC)) and the FMEDA rows citing them
A3: Task | B3: Result | C3: Mode | D3: Time | E3: What is proven | F3: Cited by
A4: abft_checker | B4: PASS | C4: prove | D4: 0.4 s | E4: a row's verdict two cycles after valid: err == (row sum != y_chk) with err_valid; err_sticky after err | F4: PE array datapath (1,056 MACs): Wrong product or sum, single-point; Weight registers (active + shadow): Bit flip in a stored weight; Weight registers (active + shadow): Stuck bit in a weight register; x / psum / token chains, skew, deskew: Bit flip in a pipeline register; x / psum / token chains, skew, deskew: Stuck pipeline register; ABFT checker (array output): Stuck at 'no error' (false negative); Accumulator SRAM (64 KB): Single-bit upset; Accumulator SRAM (64 KB): Stuck cell or decoder fault
A5: crc16_beat_bw16 | B5: PASS | C5: prove | D5: 22.5 s | E5: rtl/crc16_beat == the frozen serial reference, every crc_in, beat and word count n = 0..BW | F5: NoC interface (requests, responses): Corrupted packet, lost packet (permanent part); NoC interface (requests, responses): Corrupted packet, lost packet (transient part)
A6: crc16_beat_bw4 | B6: PASS | C6: prove | D6: 1.3 s | E6: rtl/crc16_beat == the frozen serial reference, every crc_in, beat and word count n = 0..BW | F6: NoC interface (requests, responses): Corrupted packet, lost packet (permanent part); NoC interface (requests, responses): Corrupted packet, lost packet (transient part)
A7: ecc39 | B7: PASS | C7: prove | D7: 0.4 s | E7: (39,32) SECDED: dec(enc(d)) == d clean; every single flip corrected (ce); every double flip detected (ue) | F7: Sequencer FSM, run counters, weight-buffer addressing: Wrong run order, wrong tile, early drain (permanent part); Sequencer FSM, run counters, weight-buffer addressing: Wrong run order, wrong tile, early drain (transient part); Weight buffer SRAM (v2 addition): Single-bit upset; Weight buffer SRAM (v2 addition): Multi-bit upset in one lane; chip: Shared SRAM 128 MB, soft errors
A8: link_pack_parity | B8: PASS | C8: prove | D8: 13.1 s | E8: packer -> unpacker round trip: same words, order and fields; flit parity and size; CRC flush; progress | F8: NoC interface (requests, responses): Corrupted packet, lost packet (permanent part); NoC interface (requests, responses): Corrupted packet, lost packet (transient part)
A9: link_pack_stream | B9: PASS | C9: prove | D9: 212.4 s | E9: packer -> unpacker round trip: same words, order and fields; flit parity and size; CRC flush; progress | F9: NoC interface (requests, responses): Corrupted packet, lost packet (permanent part); NoC interface (requests, responses): Corrupted packet, lost packet (transient part)
A10: lockstep_core_seq | B10: PASS | C10: prove | D10: 1.2 s | E10: two core_seq (16x8), identical inputs from reset: the 12 compared outputs equal every cycle | F10: Sequencer FSM, run counters, weight-buffer addressing: Wrong run order, wrong tile, early drain (permanent part); Sequencer FSM, run counters, weight-buffer addressing: Wrong run order, wrong tile, early drain (transient part)
A11: lockstep_requant | B11: PASS | C11: prove | D11: 15.5 s | E11: two requant (COLS = 4), stream after the table is written: out_valid equal, out_q equal while valid | F11: Requantization tables and datapath: Wrong scale, zero point or saturation (permanent part); Requantization tables and datapath: Wrong scale, zero point or saturation (transient part)
A12: noc_router | B12: PASS | C12: prove | D12: 46.9 s | E12: FIFO invariants, XY routing, odd parity dropped and flagged, no invention, a flit token kept, fairness | F12: chip: NoC and DMA engines
A13: requant_parity | B13: PASS | C13: prove | D13: 1.5 s | E13: table parity: no fault, no flag; the fault on a written entry 0 under in_valid flags the next cycle | F13: Requantization tables and datapath: Wrong scale, zero point or saturation (permanent part); Requantization tables and datapath: Wrong scale, zero point or saturation (transient part)

Sheet Evidence
A1: Mechanism evidence: v1's fault-injection tests, and v2's (the campaign, C6)
A2: Mechanism | B2: Fault injected | C2: Test | D2: Log | E2: Drop
A3: ABFT check column | B3: +1 on one product in PE(0,0) for one cycle | C3: T2 (model and 32x32 RTL), C4 | D3: sim/neosim_mac_core_32x32.log, sim/neosim_conv_core.log | E3: 0.1-0.3
A4: ABFT at drain | B4: bit flip in accumulator memory; corrupted partial-sum row in flight | C4: C4, K2 | D4: sim/neosim_conv_core.log, sim/neosim_ksplit.log | E4: 0.3, 0.6
A5: Duplicated feeder control (R7) | B5: address generator corrupted for one valid cycle | C5: C5 | D5: sim/neosim_conv_core.log | E5: 0.4
A6: Lockstep sequencer (R10) | B6: drain index bit 0 flipped | C6: C7 | D6: sim/neosim_conv_core.log | E6: 0.8
A7: Duplicated requantization (R10) | B7: bit 12 of column 0 into the primary stage | C7: C8 | D7: sim/neosim_conv_core.log | E7: 0.8
A8: Weight-buffer ECC | B8: data and check bits flipped in stored codewords | C8: C9 | D8: sim/neosim_conv_core_late.log | E8: 0.12
A9: Requant table parity | B9: multiplier bit 0 flipped | C9: C10 | D9: sim/neosim_conv_core_late.log | E9: 0.12
A10: Link parity | B10: flit bit flipped on a link | C10: N2 | D10: sim/neosim_noc.log | E10: 0.4
A11: End-to-end CRC | B11: payload bit flipped past the last link check | C11: M3 | D11: sim/neosim_tiles.log | E11: 0.7
A12: Bank ECC | B12: data and check bits flipped in the source bank | C12: M5 | D12: sim/neosim_tiles.log | E12: 0.9
A13: Lost-flit detection | B13: a fetch-response flit dropped at the owner's port | C13: M9a | D13: sim/neosim_tiles.log | E13: 0.12
... A22: The comparator storage of 0.41 (R7 / R10) | B22: a flip in each of the twelve registers 0.41's synchronous reads added behind the comparators (the port-B address latches, inb_q, a0_q, first_oq, w_load_q, ra0_q, the accumulate's stage-0 control) | C22: C6 | D22: dv/cocotb (cocotb core) | E22: 0.43
